Workbook
Name EndDate: #REF!
Name EndWeight: #REF!
Name StartDate: #REF!
Name StartWeight: #REF!
Name TEST: #REF!
Name WeightGoal: #REF!

Sheet Summary Info
H1: CNB | I1: =AD2 | AC1: Client Name: | AD1: Two Rivers Housing Association | AM1: DISCLAIMER The Client understands that: • this report, and any communications in relation to the contents of this report, is private and confidential and intended for the Client only; • it is responsible for ensuring that all the tendered properties are the responsibility of the Client. If any sites are not the responsibility of the Client, these should be immediately identified to EIC so that these can be removed from any future supply contracts; • it is responsible for ensuring that these sites are eligible to transfer to a new supplier including ensuring that termination notices have been issued in accordance with the incumbent Energy Supplier's terms and conditions and that any debt greater than 30 days old has been cleared. Additionally the Client is aware that any objections to transfer could result in out of contract rates being applied by the incumbent supplier; • any supply contract entered into is a direct contract between the Client and the selected Energy Supplier and as such the Client will be bound by the terms and conditions provided by the Energy Supplier. It is the Clients responsibility to ensure it has read, understood and accepted the Energy Supplier’s terms and conditions before accepting any contract; • the contents are intended for informational purposes only and that EIC makes no representation (either express or implied) or other assurances (either express or implied) that the information and opinions expressed in this report are accurate, complete or up to date; • EIC is not liable for any damages or losses of any kind, whether foreseeable or not, (including, but without limitation, financial loss, damages for loss in business projects, loss of profits or other consequential losses) arising in contract, tort, or otherwise, as a direct or indirect result from action taken or decisions made as a result of reliance on material, in whole or in part, contained in the report. Nothing contained in the report constitutes financial, legal, tax or other advice, nor should any investment or any other decisions be made solely based on the report content; • where contract type specifies NCP, F(T&Cs) or NCPP, contracts may be subject to new charges or non-commodity potentially passed through by the supplier. • the report may contain price projections that are based on assumptions that are subject to variations and as such there can be no assurance that the projections contained herein will be realised; • For quotations excluding MOP and DC/DA charges, supplier metering cost estimates will be applied for comparison purposes. The client should be aware these remain subject to change within the supplier T&Cs. • whilst EIC considers that it used reasonable skill and care in producing this report that all parties must rely upon their own skill and judgement when making use of it. • The client is aware that contract values and costs do not include any VAT, discounts, levies or grants the site might be eligible for. • The client understands that prices are inclusive of any agreed commission between EIC and the client. • Price eligibility may be subject to credit checks. • The client understands that prices are valid at point of issue only, and suppliers retain the right to revoke prices without notice subject to market movement • Supplier prices and current estimated costs may also change due to industry changes, for example MHHS, which could affect any pass through charges and estimations. • Deemed prices are subject to change. Please check supplier websites for the latest published rates. • The client should inform EIC if they are a micro business. •Please note your chosen Supplier shall be entitled to charge Out of Contract Rates from the day after the end of your supply contract period •Stark shall be appointed as DC/DA via supplier nomination *The figures highlighted are indicative. The Consumption data is based on historic information or industry AQs (Annual Quantity). Actual consumption, and therefore costs, may vary. The client is responsible for checking the data appears correct and informing EIC if changes need to be made. Contract Values and Costs displayed are based on your estimated consumption and therefore directly influenced by actual usage. | BH1: Non-Commodity charges | BI1: Corona | BJ1: Crown You Fix | BK1: Ecotricity | BL1: EDF Fixed Standard | BM1: Pozitive | BN1: SEFE Shield | BO1: SSE Protect | BP1: Total Energies | BQ1: Deemed
J2: =SUM('Summary Calculations'!F1:F2) | AC2: CNB: | AD2: MON-001930 | BH2: MAM, MAP, DC/DA | BI2: P | BJ2: P | BK2: P | BL2: P | BM2: P | BN2: P | BO2: P | BP2: P | BQ2: P
AC3: Contract Renewal Date: | AD3: 01/01/2027 | BH3: NTS | BI3: P | BJ3: F | BK3: P | BL3: P | BM3: P | BN3: F | BO3: F | BP3: F | BQ3: P
AC4: Analysis version: | AD4: <v1> | BH4: UNC | BI4: P | BJ4: P | BK4: P | BL4: P | BM4: P | BN4: F | BO4: F | BP4: P | BQ4: P
J5: Total No. Sites Tendered | AC5: Presented to client: | AD5: =TODAY() | BH5: LDZ System Capacity | BI5: P | BJ5: F | BK5: P | BL5: P | BM5: P | BN5: F | BO5: F | BP5: F | BQ5: P
BH6: LDZ Customer Charge | BI6: P | BJ6: F | BK6: P | BL6: P | BM6: P | BN6: F | BO6: F | BP6: F | BQ6: P
J7: =Analysis!O7 | AC7: Supplier Reference | AD7: Supplier | AE7: Contract Duration (months) | AF7: Contract Type | AG7: Energy Type | AH7: Payment Type | AI7: Payment Duration | AJ7: Annual Contract Value* | AK7: Annual Contract Value % Diff vs Current* | AL7: Total Difference Over Contract* | BH7: LDZ Exit Capacity NTS | BI7: P | BJ7: F | BK7: P | BL7: P | BM7: P | BN7: F | BO7: F | BP7: F | BQ7: P
BH8: GDN Entry Commodity Charge | BI8: P | BJ8: P | BK8: P | BL8: P | BM8: P | BN8: F | BO8: F | BP8: P | BQ8: P
BH9: UIG | BI9: P | BJ9: P | BK9: P | BL9: P | BM9: P | BN9: F | BO9: F | BP9: P | BQ9: P
AC10: Current | AD10: Current | AE10: Current | AF10: Current | AG10: Current | AH10: Current | AI10: Current | AJ10: =INDEX(Analysis!$A$7:$DV$8,1,MATCH(AC10,Analysis!$A$8:$DV$8,0)) | BH10: BSC | BI10: P | BJ10: P | BK10: P | BL10: P | BM10: P | BN10: F | BO10: F | BP10: P | BQ10: P
J11: Total Annual Consumption* | AD11: EDF Energy | AE11: 12 | AF11: Fixed within T&C Conditions | AG11: Brown | AH11: BACS | AI11: 28 days | AJ11: =INDEX(Analysis!$A$7:$DV$8,1,MATCH(AC11,Analysis!$A$8:$DV$8,0)) | AK11: =(AJ11-$AJ$10)/$AJ$10*100 | AL11: =(AJ11-$AJ$10)/12*AE11 | BH11: Government Levies/regulations | BI11: P | BJ11: P | BK11: P | BL11: P | BM11: P | BN11: P | BO11: P | BP11: P | BQ11: P
AF12: Fixed within T&C Conditions | AG12: Brown | AH12: BACS | AI12: 21 days | AJ12: =INDEX(Analysis!$A$7:$DV$8,1,MATCH(AC12,Analysis!$A$8:$DV$8,0)) | AK12: =(AJ12-$AJ$10)/$AJ$10*100 | AL12: =(AJ12-$AJ$10)/12*AE12 | BH12: Additional Charges
J13: =AD3 | AF13: Fixed within T&C Conditions | AG13: Brown | AH13: BACS | AI13: 21 days | AJ13: =INDEX(Analysis!$A$7:$DV$8,1,MATCH(AC13,Analysis!$A$8:$DV$8,0)) | AK13: =(AJ13-$AJ$10)/$AJ$10*100 | AL13: =(AJ13-$AJ$10)/12*AE13 | BH13: Volume Tolerance | BI13: TBC | BJ13: 0.25 | BK13: 0.2 | BL13: 0.2 | BM13: TBC | BN13: 0.2 | BO13: >723K = 70/130 | BP13: 0.2 | BQ13: T&Cs
AF14: Fixed within T&C Conditions | AG14: Brown | AH14: BACS | AI14: 21 days | AJ14: =INDEX(Analysis!$A$7:$DV$8,1,MATCH(AC14,Analysis!$A$8:$DV$8,0)) | AK14: =(AJ14-$AJ$10)/$AJ$10*100 | AL14: =(AJ14-$AJ$10)/12*AE14 | BH14: RGGO/REGGO Backed on Renewable | BI14: Yes | BJ14: Yes | BK14: No | BL14: No | BM14: Yes | BN14: Yes | BO14: Yes | BP14: Yes | BQ14: T&Cs
AF15: Fixed within T&C Conditions | AG15: Brown | AH15: BACS | AI15: 21 days | AJ15: =INDEX(Analysis!$A$7:$DV$8,1,MATCH(AC15,Analysis!$A$8:$DV$8,0)) | AK15: =(AJ15-$AJ$10)/$AJ$10*100 | AL15: =(AJ15-$AJ$10)/12*AE15 | BH15: Site Removal Fees | BI15: Yes | BJ15: Yes | BK15: Yes | BL15: Yes | BM15: Yes | BN15: Yes | BO15: Yes | BP15: Yes | BQ15: T&Cs
AF16: Fixed within T&C Conditions | AG16: Brown | AH16: BACS | AI16: 21 days | AJ16: =INDEX(Analysis!$A$7:$DV$8,1,MATCH(AC16,Analysis!$A$8:$DV$8,0)) | AK16: =(AJ16-$AJ$10)/$AJ$10*100 | AL16: =(AJ16-$AJ$10)/12*AE16 | BH16: Late Payment Fees | BI16: Yes | BJ16: Yes | BK16: Yes | BL16: Yes | BM16: Yes | BN16: Yes | BO16: Yes | BP16: Yes | BQ16: T&Cs
J17: Contract Start Date | AF17: Fixed within T&C Conditions | AG17: Brown | AH17: BACS | AI17: 21 days | AJ17: =INDEX(Analysis!$A$7:$DV$8,1,MATCH(AC17,Analysis!$A$8:$DV$8,0)) | AK17: =(AJ17-$AJ$10)/$AJ$10*100 | AL17: =(AJ17-$AJ$10)/12*AE17 | BH17: Additional comments
AF18: Fixed within T&C Conditions | AG18: Brown | AH18: BACS | AI18: 21 days | AJ18: =INDEX(Analysis!$A$7:$DV$8,1,MATCH(AC18,Analysis!$A$8:$DV$8,0)) | AK18: =(AJ18-$AJ$10)/$AJ$10*100 | AL18: =(AJ18-$AJ$10)/12*AE18
J19: =Analysis!P7 | AF19: Fixed within T&C Conditions | AG19: Brown | AH19: BACS | AI19: 21 days | AJ19: =INDEX(Analysis!$A$7:$DV$8,1,MATCH(AC19,Analysis!$A$8:$DV$8,0)) | AK19: =(AJ19-$AJ$10)/$AJ$10*100 | AL19: =(AJ19-$AJ$10)/12*AE19 | BH19: Key
AF20: Fixed within T&C Conditions | AG20: Brown | AH20: BACS | AI20: 21 days | AJ20: =INDEX(Analysis!$A$7:$DV$8,1,MATCH(AC20,Analysis!$A$8:$DV$8,0)) | AK20: =(AJ20-$AJ$10)/$AJ$10*100 | AL20: =(AJ20-$AJ$10)/12*AE20 | BH20: F - Fully Inclusive and rates should not change
AF21: Fixed within T&C Conditions | AG21: Brown | AH21: BACS | AI21: 21 days | AJ21: =INDEX(Analysis!$A$7:$DV$8,1,MATCH(AC21,Analysis!$A$8:$DV$8,0)) | AK21: =(AJ21-$AJ$10)/$AJ$10*100 | AL21: =(AJ21-$AJ$10)/12*AE21 | BH21: P - Inclusive in rates however potentially pass-through
AF22: Fixed within T&C Conditions | AG22: Brown | AH22: BACS | AI22: 21 days | AJ22: =INDEX(Analysis!$A$7:$DV$8,1,MATCH(AC22,Analysis!$A$8:$DV$8,0)) | AK22: =(AJ22-$AJ$10)/$AJ$10*100 | AL22: =(AJ22-$AJ$10)/12*AE22 | BH22: N - Pass through and not included in rates
J23: Current Expenditure* | AF23: Fixed within T&C Conditions | AG23: Brown | AH23: BACS | AI23: 21 days | AJ23: =INDEX(Analysis!$A$7:$DV$8,1,MATCH(AC23,Analysis!$A$8:$DV$8,0)) | AK23: =(AJ23-$AJ$10)/$AJ$10*100 | AL23: =(AJ23-$AJ$10)/12*AE23
AF24: Fixed within T&C Conditions | AG24: Brown | AH24: BACS | AI24: 21 days | AJ24: =INDEX(Analysis!$A$7:$DV$8,1,MATCH(AC24,Analysis!$A$8:$DV$8,0)) | AK24: =(AJ24-$AJ$10)/$AJ$10*100 | AL24: =(AJ24-$AJ$10)/12*AE24
J25: =AD4 | AF25: Fixed within T&C Conditions | AG25: Brown | AH25: BACS | AI25: 21 days | AJ25: =INDEX(Analysis!$A$7:$DV$8,1,MATCH(AC25,Analysis!$A$8:$DV$8,0)) | AK25: =(AJ25-$AJ$10)/$AJ$10*100 | AL25: =(AJ25-$AJ$10)/12*AE25
AF26: Fixed within T&C Conditions | AG26: Brown | AH26: BACS | AI26: 21 days | AJ26: =INDEX(Analysis!$A$7:$DV$8,1,MATCH(AC26,Analysis!$A$8:$DV$8,0)) | AK26: =(AJ26-$AJ$10)/$AJ$10*100 | AL26: =(AJ26-$AJ$10)/12*AE26
AF27: Fixed within T&C Conditions | AG27: Brown | AH27: BACS | AI27: 21 days | AJ27: =INDEX(Analysis!$A$7:$DV$8,1,MATCH(AC27,Analysis!$A$8:$DV$8,0)) | AK27: =(AJ27-$AJ$10)/$AJ$10*100 | AL27: =(AJ27-$AJ$10)/12*AE27
AF28: Fixed within T&C Conditions | AG28: Brown | AH28: BACS | AI28: 21 days | AJ28: =INDEX(Analysis!$A$7:$DV$8,1,MATCH(AC28,Analysis!$A$8:$DV$8,0)) | AK28: =(AJ28-$AJ$10)/$AJ$10*100 | AL28: =(AJ28-$AJ$10)/12*AE28
J29: Analysis Version | AF29: Fixed within T&C Conditions | AG29: Brown | AH29: BACS | AI29: 21 days | AJ29: =INDEX(Analysis!$A$7:$DV$8,1,MATCH(AC29,Analysis!$A$8:$DV$8,0)) | AK29: =(AJ29-$AJ$10)/$AJ$10*100 | AL29: =(AJ29-$AJ$10)/12*AE29
AF30: Fixed within T&C Conditions | AG30: Brown | AH30: BACS | AI30: 21 days | AJ30: =INDEX(Analysis!$A$7:$DV$8,1,MATCH(AC30,Analysis!$A$8:$DV$8,0)) | AK30: =(AJ30-$AJ$10)/$AJ$10*100 | AL30: =(AJ30-$AJ$10)/12*AE30
J31: =AD5 | AF31: Fixed within T&C Conditions | AG31: Brown | AH31: BACS | AI31: 21 days | AJ31: =INDEX(Analysis!$A$7:$DV$8,1,MATCH(AC31,Analysis!$A$8:$DV$8,0)) | AK31: =(AJ31-$AJ$10)/$AJ$10*100 | AL31: =(AJ31-$AJ$10)/12*AE31
AF32: Fixed within T&C Conditions | AG32: Brown | AH32: BACS | AI32: 21 days | AJ32: =INDEX(Analysis!$A$7:$DV$8,1,MATCH(AC32,Analysis!$A$8:$DV$8,0)) | AK32: =(AJ32-$AJ$10)/$AJ$10*100 | AL32: =(AJ32-$AJ$10)/12*AE32
AF33: Fixed within T&C Conditions | AG33: Brown | AH33: BACS | AI33: 21 days | AJ33: =INDEX(Analysis!$A$7:$DV$8,1,MATCH(AC33,Analysis!$A$8:$DV$8,0)) | AK33: =(AJ33-$AJ$10)/$AJ$10*100 | AL33: =(AJ33-$AJ$10)/12*AE33
AF34: Fixed within T&C Conditions | AG34: Brown | AH34: BACS | AI34: 21 days | AJ34: =INDEX(Analysis!$A$7:$DV$8,1,MATCH(AC34,Analysis!$A$8:$DV$8,0)) | AK34: =(AJ34-$AJ$10)/$AJ$10*100 | AL34: =(AJ34-$AJ$10)/12*AE34
J35: Date Presented to Client | AF35: Fixed within T&C Conditions | AG35: Brown | AH35: BACS | AI35: 21 days | AJ35: =INDEX(Analysis!$A$7:$DV$8,1,MATCH(AC35,Analysis!$A$8:$DV$8,0)) | AK35: =(AJ35-$AJ$10)/$AJ$10*100 | AL35: =(AJ35-$AJ$10)/12*AE35
AF36: Fixed within T&C Conditions | AG36: Brown | AH36: BACS | AI36: 21 days | AJ36: =INDEX(Analysis!$A$7:$DV$8,1,MATCH(AC36,Analysis!$A$8:$DV$8,0)) | AK36: =(AJ36-$AJ$10)/$AJ$10*100 | AL36: =(AJ36-$AJ$10)/12*AE36
J37: =AD2 | AF37: Fixed within T&C Conditions | AG37: Brown | AH37: BACS | AI37: 21 days | AJ37: =INDEX(Analysis!$A$7:$DV$8,1,MATCH(AC37,Analysis!$A$8:$DV$8,0)) | AK37: =(AJ37-$AJ$10)/$AJ$10*100 | AL37: =(AJ37-$AJ$10)/12*AE37
A41: EIC Partnership | J41: Contract Reference
L43: * The graph above does not show intra-day fluctuations in the wholesale price.

Sheet Summary Calculations
A1: Supplier | B1: Current | E1: Total number of non-IGT sites | F1: =COUNTA(Analysis!M10:M1000)-'Summary Calculations'!F2
A2: Contract Type | B2: (All) | E2: Total number of IGT sites | F2: =COUNTIF(Analysis!M10:M1000,"IGT")
A3: Energy Type | B3: (All) | E3: Total number of sites | F3: =SUM(F1:F2)
A4: Payment Type | B4: (All)
A5: Payment Duration | B5: (All)
A6: Contract Duration (months) | B6: (All)

Sheet Analysis
A1: Gas Quote Analysis | T1: Date | W1: Date | Z1: Date | AC1: Date | AF1: Date | AI1: Date | AL1: Date | AO1: Date | AR1: Date | AU1: Date | AX1: Date | BA1: Date | BD1: Date | BG1: Date | BJ1: Date | BM1: Date | BP1: Date | BS1: Date | BV1: Date | BY1: Date | CB1: Date | CE1: Date | CH1: Date | CK1: Date | CN1: Date | CQ1: Date | CT1: Date | CW1: Date | CZ1: Date
T2: Prev Total | W2: Prev Total | Z2: Prev Total | AC2: Prev Total | AF2: Prev Total | AI2: Prev Total | AL2: Prev Total | AO2: Prev Total | AR2: Prev Total | AU2: Prev Total | AX2: Prev Total | BA2: Prev Total | BD2: Prev Total | BG2: Prev Total | BJ2: Prev Total | BM2: Prev Total | BP2: Prev Total | BS2: Prev Total | BV2: Prev Total | BY2: Prev Total | CB2: Prev Total | CE2: Prev Total | CH2: Prev Total | CK2: Prev Total | CN2: Prev Total | CQ2: Prev Total | CT2: Prev Total | CW2: Prev Total | CZ2: Prev Total
U3: =S7-U2 | X3: =V7-X2 | AA3: =Y7-AA2 | AD3: =AB7-AD2 | AG3: =AE7-AG2 | AJ3: =AH7-AJ2 | AM3: =AK7-AM2 | AP3: =AN7-AP2 | AS3: =AQ7-AS2 | AV3: =AT7-AV2 | AY3: =AW7-AY2 | BB3: =AZ7-BB2 | BE3: =BC7-BE2 | BH3: =BF7-BH2 | BK3: =BI7-BK2 | BN3: =BL7-BN2 | BQ3: =BO7-BQ2 | BT3: =BR7-BT2 | BW3: =BU7-BW2 | BZ3: =BX7-BZ2 | CC3: =CA7-CC2 | CF3: =CD7-CF2 | CI3: =CG7-CI2 | CL3: =CJ7-CL2 | CO3: =CM7-CO2 | CR3: =CP7-CR2 | CU3: =CS7-CU2 | CX3: =CV7-CX2 | DA3: =CY7-DA2
U5: =(S7-$P$7)/$P$7 | X5: =(V7-$P$7)/$P$7 | AA5: =(Y7-$P$7)/$P$7 | AD5: =(AB7-$P$7)/$P$7 | AG5: =(AE7-$P$7)/$P$7 | AJ5: =(AH7-$P$7)/$P$7 | AM5: =(AK7-$P$7)/$P$7 | AP5: =(AN7-$P$7)/$P$7 | AS5: =(AQ7-$P$7)/$P$7 | AV5: =(AT7-$P$7)/$P$7 | AY5: =(AW7-$P$7)/$P$7 | BB5: =(AZ7-$P$7)/$P$7 | BE5: =(BC7-$P$7)/$P$7 | BH5: =(BF7-$P$7)/$P$7 | BK5: =(BI7-$P$7)/$P$7 | BN5: =(BL7-$P$7)/$P$7 | BQ5: =(BO7-$P$7)/$P$7 | BT5: =(BR7-$P$7)/$P$7 | BW5: =(BU7-$P$7)/$P$7 | BZ5: =(BX7-$P$7)/$P$7 | CC5: =(CA7-$P$7)/$P$7 | CF5: =(CD7-$P$7)/$P$7 | CI5: =(CG7-$P$7)/$P$7 | CL5: =(CJ7-$P$7)/$P$7 | CO5: =(CM7-$P$7)/$P$7 | CR5: =(CP7-$P$7)/$P$7 | CU5: =(CS7-$P$7)/$P$7 | CX5: =(CV7-$P$7)/$P$7 | DA5: =(CY7-$P$7)/$P$7 | DD5: =(DB7-$P$7)/$P$7 | DG5: =(DE7-$P$7)/$P$7 | DJ5: =(DH7-$P$7)/$P$7 | DM5: =(DK7-$P$7)/$P$7 | DP5: =(DN7-$P$7)/$P$7 | DS5: =(DQ7-$P$7)/$P$7 | DV5: =(DT7-$P$7)/$P$7
U6: =(S7-$P$7) | X6: =(V7-$P$7) | AA6: =(Y7-$P$7) | AD6: =(AB7-$P$7) | AG6: =(AE7-$P$7) | AJ6: =(AH7-$P$7) | AM6: =(AK7-$P$7) | AP6: =(AN7-$P$7) | AS6: =(AQ7-$P$7) | AV6: =(AT7-$P$7) | AY6: =(AW7-$P$7) | BB6: =(AZ7-$P$7) | BE6: =(BC7-$P$7) | BH6: =(BF7-$P$7) | BK6: =(BI7-$P$7) | BN6: =(BL7-$P$7) | BQ6: =(BO7-$P$7) | BT6: =(BR7-$P$7) | BW6: =(BU7-$P$7) | BZ6: =(BX7-$P$7) | CC6: =(CA7-$P$7) | CF6: =(CD7-$P$7) | CI6: =(CG7-$P$7) | CL6: =(CJ7-$P$7) | CO6: =(CM7-$P$7) | CR6: =(CP7-$P$7) | CU6: =(CS7-$P$7) | CX6: =(CV7-$P$7) | DA6: =(CY7-$P$7) | DD6: =(DB7-$P$7) | DG6: =(DE7-$P$7) | DJ6: =(DH7-$P$7) | DM6: =(DK7-$P$7) | DP6: =(DN7-$P$7) | DS6: =(DQ7-$P$7) | DV6: =(DT7-$P$7)
O7: =SUM(O10:O1211) | P7: =SUM(R10:R1000) | S7: =SUM(U10:U1000) | V7: =SUM(X10:X1000) | Y7: =SUM(AA10:AA1000) | AB7: =SUM(AD10:AD1000) | AE7: =SUM(AG10:AG1000) | AH7: =SUM(AJ10:AJ1000) | AK7: =SUM(AM10:AM1000) | AN7: =SUM(AP10:AP1000) | AQ7: =SUM(AS10:AS1000) | AT7: =SUM(AV10:AV1000) | AW7: =SUM(AY10:AY1000) | AZ7: =SUM(BB10:BB1000) | BC7: =SUM(BE10:BE1000) | BF7: =SUM(BH10:BH1000) | BI7: =SUM(BK10:BK1000) | BL7: =SUM(BN10:BN1000) | BO7: =SUM(BQ10:BQ1000) | BR7: =SUM(BT10:BT1000) | BU7: =SUM(BW10:BW1000) | BX7: =SUM(BZ10:BZ1000) | CA7: =SUM(CC10:CC1000) | CD7: =SUM(CF10:CF1000) | CG7: =SUM(CI10:CI1000) | CJ7: =SUM(CL10:CL1000) | CM7: =SUM(CO10:CO1000) | CP7: =SUM(CR10:CR1000) | CS7: =SUM(CU10:CU1000) | CV7: =SUM(CX10:CX1000) | CY7: =SUM(DA10:DA1000) | DB7: =SUM(DD10:DD1000) | DE7: =SUM(DG10:DG1000) | DH7: =SUM(DJ10:DJ1000) | DK7: =SUM(DM10:DM1000) | DN7: =SUM(DP10:DP1000) | DQ7: =SUM(DS10:DS1000) | DT7: =SUM(DV10:DV1000)
B8: Site Details | K8: Meter Details | O8: Current Consumption | P8: Current
A9: Notes | B9: Location Reference | C9: Client Reference | D9: Address | I9: Start date | J9: Current Supplier | K9: MSN | L9: MPRN | M9: IGT? | N9: IGT Name | O9: Annual (kWh) | P9: Unit Rate (p/kWh) | Q9: Standing Charge (£/month) | R9: Annual Cost (£) | S9: Unit Rate (p/kWh) | T9: Standing Charge (£/month) | U9: Annual Cost (£) | V9: Unit Rate (p/kWh) | W9: Standing Charge (£/month) | X9: Annual Cost (£) | Y9: Unit Rate (p/kWh) | Z9: Standing Charge (£/month) | AA9: Annual Cost (£) | AB9: Unit Rate (p/kWh) | AC9: Standing Charge (£/month) | AD9: Annual Cost (£) | AE9: Unit Rate (p/kWh) | AF9: Standing Charge (£/month) | AG9: Annual Cost (£) | AH9: Unit Rate (p/kWh) | AI9: Standing Charge (£/month) | AJ9: Annual Cost (£) | AK9: Unit Rate (p/kWh) | AL9: Standing Charge (£/month) | AM9: Annual Cost (£) | AN9: Unit Rate (p/kWh) | AO9: Standing Charge (£/month) | AP9: Annual Cost (£) | AQ9: Unit Rate (p/kWh) | AR9: Standing Charge (£/month) | AS9: Annual Cost (£) | AT9: Unit Rate (p/kWh) | AU9: Standing Charge (£/month) | AV9: Annual Cost (£) | AW9: Unit Rate (p/kWh) | AX9: Standing Charge (£/month) | AY9: Annual Cost (£) | AZ9: Unit Rate (p/kWh) | BA9: Standing Charge (£/month) | BB9: Annual Cost (£) | BC9: Unit Rate (p/kWh) | BD9: Standing Charge (£/month) | BE9: Annual Cost (£) | BF9: Unit Rate (p/kWh) | BG9: Standing Charge (£/month) | BH9: Annual Cost (£) | BI9: Unit Rate (p/kWh) | BJ9: Standing Charge (£/month) | BK9: Annual Cost (£) | BL9: Unit Rate (p/kWh) | BM9: Standing Charge (£/month) | BN9: Annual Cost (£) | BO9: Unit Rate (p/kWh) | BP9: Standing Charge (£/month) | BQ9: Annual Cost (£) | BR9: Unit Rate (p/kWh) | BS9: Standing Charge (£/month) | BT9: Annual Cost (£) | BU9: Unit Rate (p/kWh) | BV9: Standing Charge (£/month) | BW9: Annual Cost (£) | BX9: Unit Rate (p/kWh) | BY9: Standing Charge (£/month) | BZ9: Annual Cost (£) | CA9: Unit Rate (p/kWh) | CB9: Standing Charge (£/month) | CC9: Annual Cost (£) | CD9: Unit Rate (p/kWh) | CE9: Standing Charge (£/month) | CF9: Annual Cost (£) | CG9: Unit Rate (p/kWh) | CH9: Standing Charge (£/month) | CI9: Annual Cost (£) | CJ9: Unit Rate (p/kWh) | CK9: Standing Charge (£/month) | CL9: Annual Cost (£) | CM9: Unit Rate (p/kWh) | CN9: Standing Charge (£/month) | CO9: Annual Cost (£) | CP9: Unit Rate (p/kWh) | CQ9: Standing Charge (£/month) | CR9: Annual Cost (£) | CS9: Unit Rate (p/kWh) | CT9: Standing Charge (£/month) | CU9: Annual Cost (£) | CV9: Unit Rate (p/kWh) | CW9: Standing Charge (£/month) | CX9: Annual Cost (£) | CY9: Unit Rate (p/kWh) | CZ9: Standing Charge (£/month) | DA9: Annual Cost (£) | DB9: Unit Rate (p/kWh) | DC9: Standing Charge (£/month) | DD9: Annual Cost (£) | DE9: Unit Rate (p/kWh) | DF9: Standing Charge (£/month) | DG9: Annual Cost (£) | DH9: Unit Rate (p/kWh) | DI9: Standing Charge (£/month) | DJ9: Annual Cost (£) | DK9: Unit Rate (p/kWh) | DL9: Standing Charge (£/month) | DM9: Annual Cost (£) | DN9: Unit Rate (p/kWh) | DO9: Standing Charge (£/month) | DP9: Annual Cost (£) | DQ9: Unit Rate (p/kWh) | DR9: Standing Charge (£/month) | DS9: Annual Cost (£) | DT9: Unit Rate (p/kWh) | DU9: Standing Charge (£/month) | DV9: Annual Cost (£)
B10: 56 | C10: 21/111 | D10: Ryelands Road,Communal Centre | G10: Lydney | H10: UK | J10: 01-Jan-2027 | K10: 8 | L10: E6F11035992100 | M10: 4161164101 | N10: =IF(ISERROR(INDEX('Meter Type Data'!$B$2:$D$1165,SUMPRODUCT(--('Meter Type Data'!$B$2:$B$1165<=Analysis!L10)*('Meter Type Data'!$C$2:$C$1165>=Analysis!L10),ROW('Meter Type Data'!$B$2:$B$1165))-1,3))," ",INDEX('Meter Type Data'!$B$2:$D$1165,SUMPRODUCT(--('Meter Type Data'!$B$2:$B$1165<=Analysis!L10)*('Meter Type Data'!$C$2:$C$1165>=Analysis!L10),ROW('Meter Type Data'!$B$2:$B$1165))-1,3)) | P10: 8.4392 | Q10: 8.4392 | R10: 177.7957 | U10: =(($O10*S10)/100)+(T10*12) | X10: =(($O10*V10)/100)+(W10*12) | AA10: =(($O10*Y10)/100)+(Z10*12) | AD10: =(($O10*AB10)/100)+(AC10*12) | AG10: =(($O10*AE10)/100)+(AF10*12) | AJ10: =(($O10*AH10)/100)+(AI10*12) | AM10: =(($O10*AK10)/100)+(AL10*12) | AP10: =(($O10*AN10)/100)+(AO10*12) | AS10: =(($O10*AQ10)/100)+(AR10*12) | AV10: =(($O10*AT10)/100)+(AU10*12) | AY10: =(($O10*AW10)/100)+(AX10*12) | BB10: =(($O10*AZ10)/100)+(BA10*12) | BE10: =(($O10*BC10)/100)+(BD10*12) | BH10: =(($O10*BF10)/100)+(BG10*12) | BK10: =(($O10*BI10)/100)+(BJ10*12) | BN10: =(($O10*BL10)/100)+(BM10*12) | BQ10: =(($O10*BO10)/100)+(BP10*12) | BT10: =(($O10*BR10)/100)+(BS10*12) | BW10: =(($O10*BU10)/100)+(BV10*12) | BZ10: =(($O10*BX10)/100)+(BY10*12) | CC10: =(($O10*CA10)/100)+(CB10*12) | CF10: =(($O10*CD10)/100)+(CE10*12) | CI10: =(($O10*CG10)/100)+(CH10*12) | CL10: =(($O10*CJ10)/100)+(CK10*12) | CO10: =(($O10*CM10)/100)+(CN10*12) | CR10: =(($O10*CP10)/100)+(CQ10*12) | CU10: =(($O10*CS10)/100)+(CT10*12) | CX10: =(($O10*CV10)/100)+(CW10*12) | DA10: =(($O10*CY10)/100)+(CZ10*12) | DD10: =(($O10*DB10)/100)+(DC10*12) | DG10: =(($O10*DE10)/100)+(DF10*12) | DJ10: =(($O10*DH10)/100)+(DI10*12) | DM10: =(($O10*DK10)/100)+(DL10*12) | DP10: =(($O10*DN10)/100)+(DO10*12) | DS10: =(($O10*DQ10)/100)+(DR10*12) | DV10: =(($O10*DT10)/100)+(DU10*12)
B11: 64 | C11: 21/103 | D11: 2 Crawshay Place ,Communal Centre | G11: Cinderford | H11: UK | J11: 01-Jan-2027 | K11: 8 | L11: E6F20451512200 | M11: 4155913310 | N11: =IF(ISERROR(INDEX('Meter Type Data'!$B$2:$D$1165,SUMPRODUCT(--('Meter Type Data'!$B$2:$B$1165<=Analysis!L11)*('Meter Type Data'!$C$2:$C$1165>=Analysis!L11),ROW('Meter Type Data'!$B$2:$B$1165))-1,3))," ",INDEX('Meter Type Data'!$B$2:$D$1165,SUMPRODUCT(--('Meter Type Data'!$B$2:$B$1165<=Analysis!L11)*('Meter Type Data'!$C$2:$C$1165>=Analysis!L11),ROW('Meter Type Data'!$B$2:$B$1165))-1,3)) | P11: 8.4119 | Q11: 8.4119 | R11: 86.0756 | U11: =(($O11*S11)/100)+(T11*12) | X11: =(($O11*V11)/100)+(W11*12) | AA11: =(($O11*Y11)/100)+(Z11*12) | AD11: =(($O11*AB11)/100)+(AC11*12) | AG11: =(($O11*AE11)/100)+(AF11*12) | AJ11: =(($O11*AH11)/100)+(AI11*12) | AM11: =(($O11*AK11)/100)+(AL11*12) | AP11: =(($O11*AN11)/100)+(AO11*12) | AS11: =(($O11*AQ11)/100)+(AR11*12) | AV11: =(($O11*AT11)/100)+(AU11*12) | AY11: =(($O11*AW11)/100)+(AX11*12) | BB11: =(($O11*AZ11)/100)+(BA11*12) | BE11: =(($O11*BC11)/100)+(BD11*12) | BH11: =(($O11*BF11)/100)+(BG11*12) | BK11: =(($O11*BI11)/100)+(BJ11*12) | BN11: =(($O11*BL11)/100)+(BM11*12) | BQ11: =(($O11*BO11)/100)+(BP11*12) | BT11: =(($O11*BR11)/100)+(BS11*12) | BW11: =(($O11*BU11)/100)+(BV11*12) | BZ11: =(($O11*BX11)/100)+(BY11*12) | CC11: =(($O11*CA11)/100)+(CB11*12) | CF11: =(($O11*CD11)/100)+(CE11*12) | CI11: =(($O11*CG11)/100)+(CH11*12) | CL11: =(($O11*CJ11)/100)+(CK11*12) | CO11: =(($O11*CM11)/100)+(CN11*12) | CR11: =(($O11*CP11)/100)+(CQ11*12) | CU11: =(($O11*CS11)/100)+(CT11*12) | CX11: =(($O11*CV11)/100)+(CW11*12) | DA11: =(($O11*CY11)/100)+(CZ11*12) | DD11: =(($O11*DB11)/100)+(DC11*12) | DG11: =(($O11*DE11)/100)+(DF11*12) | DJ11: =(($O11*DH11)/100)+(DI11*12) | DM11: =(($O11*DK11)/100)+(DL11*12) | DP11: =(($O11*DN11)/100)+(DO11*12) | DS11: =(($O11*DQ11)/100)+(DR11*12) | DV11: =(($O11*DT11)/100)+(DU11*12)
B12: 65 | C12: 21/105 | D12: Birch Road,Mile End | G12: Coleford | H12: UK | J12: 01-Jan-2027 | K12: 8 | L12: G4F10922642100 | M12: 4155865606 | N12: =IF(ISERROR(INDEX('Meter Type Data'!$B$2:$D$1165,SUMPRODUCT(--('Meter Type Data'!$B$2:$B$1165<=Analysis!L12)*('Meter Type Data'!$C$2:$C$1165>=Analysis!L12),ROW('Meter Type Data'!$B$2:$B$1165))-1,3))," ",INDEX('Meter Type Data'!$B$2:$D$1165,SUMPRODUCT(--('Meter Type Data'!$B$2:$B$1165<=Analysis!L12)*('Meter Type Data'!$C$2:$C$1165>=Analysis!L12),ROW('Meter Type Data'!$B$2:$B$1165))-1,3)) | P12: 8.4078 | Q12: 8.4078 | R12: 182.4286 | U12: =(($O12*S12)/100)+(T12*12) | X12: =(($O12*V12)/100)+(W12*12) | AA12: =(($O12*Y12)/100)+(Z12*12) | AD12: =(($O12*AB12)/100)+(AC12*12) | AG12: =(($O12*AE12)/100)+(AF12*12) | AJ12: =(($O12*AH12)/100)+(AI12*12) | AM12: =(($O12*AK12)/100)+(AL12*12) | AP12: =(($O12*AN12)/100)+(AO12*12) | AS12: =(($O12*AQ12)/100)+(AR12*12) | AV12: =(($O12*AT12)/100)+(AU12*12) | AY12: =(($O12*AW12)/100)+(AX12*12) | BB12: =(($O12*AZ12)/100)+(BA12*12) | BE12: =(($O12*BC12)/100)+(BD12*12) | BH12: =(($O12*BF12)/100)+(BG12*12) | BK12: =(($O12*BI12)/100)+(BJ12*12) | BN12: =(($O12*BL12)/100)+(BM12*12) | BQ12: =(($O12*BO12)/100)+(BP12*12) | BT12: =(($O12*BR12)/100)+(BS12*12) | BW12: =(($O12*BU12)/100)+(BV12*12) | BZ12: =(($O12*BX12)/100)+(BY12*12) | CC12: =(($O12*CA12)/100)+(CB12*12) | CF12: =(($O12*CD12)/100)+(CE12*12) | CI12: =(($O12*CG12)/100)+(CH12*12) | CL12: =(($O12*CJ12)/100)+(CK12*12) | CO12: =(($O12*CM12)/100)+(CN12*12) | CR12: =(($O12*CP12)/100)+(CQ12*12) | CU12: =(($O12*CS12)/100)+(CT12*12) | CX12: =(($O12*CV12)/100)+(CW12*12) | DA12: =(($O12*CY12)/100)+(CZ12*12) | DD12: =(($O12*DB12)/100)+(DC12*12) | DG12: =(($O12*DE12)/100)+(DF12*12) | DJ12: =(($O12*DH12)/100)+(DI12*12) | DM12: =(($O12*DK12)/100)+(DL12*12) | DP12: =(($O12*DN12)/100)+(DO12*12) | DS12: =(($O12*DQ12)/100)+(DR12*12) | DV12: =(($O12*DT12)/100)+(DU12*12)
B13: 72 | C13: 21/109 | D13: Grouped Accommodation ,Parkside,Mile End | G13: Coleford | H13: UK | J13: 01-Jan-2027 | K13: 8 | L13: E6F20348032200 | M13: 4155732306 | N13: =IF(ISERROR(INDEX('Meter Type Data'!$B$2:$D$1165,SUMPRODUCT(--('Meter Type Data'!$B$2:$B$1165<=Analysis!L13)*('Meter Type Data'!$C$2:$C$1165>=Analysis!L13),ROW('Meter Type Data'!$B$2:$B$1165))-1,3))," ",INDEX('Meter Type Data'!$B$2:$D$1165,SUMPRODUCT(--('Meter Type Data'!$B$2:$B$1165<=Analysis!L13)*('Meter Type Data'!$C$2:$C$1165>=Analysis!L13),ROW('Meter Type Data'!$B$2:$B$1165))-1,3)) | P13: 8.4088 | Q13: 8.4088 | R13: 143.5391 | U13: =(($O13*S13)/100)+(T13*12) | X13: =(($O13*V13)/100)+(W13*12) | AA13: =(($O13*Y13)/100)+(Z13*12) | AD13: =(($O13*AB13)/100)+(AC13*12) | AG13: =(($O13*AE13)/100)+(AF13*12) | AJ13: =(($O13*AH13)/100)+(AI13*12) | AM13: =(($O13*AK13)/100)+(AL13*12) | AP13: =(($O13*AN13)/100)+(AO13*12) | AS13: =(($O13*AQ13)/100)+(AR13*12) | AV13: =(($O13*AT13)/100)+(AU13*12) | AY13: =(($O13*AW13)/100)+(AX13*12) | BB13: =(($O13*AZ13)/100)+(BA13*12) | BE13: =(($O13*BC13)/100)+(BD13*12) | BH13: =(($O13*BF13)/100)+(BG13*12) | BK13: =(($O13*BI13)/100)+(BJ13*12) | BN13: =(($O13*BL13)/100)+(BM13*12) | BQ13: =(($O13*BO13)/100)+(BP13*12) | BT13: =(($O13*BR13)/100)+(BS13*12) | BW13: =(($O13*BU13)/100)+(BV13*12) | BZ13: =(($O13*BX13)/100)+(BY13*12) | CC13: =(($O13*CA13)/100)+(CB13*12) | CF13: =(($O13*CD13)/100)+(CE13*12) | CI13: =(($O13*CG13)/100)+(CH13*12) | CL13: =(($O13*CJ13)/100)+(CK13*12) | CO13: =(($O13*CM13)/100)+(CN13*12) | CR13: =(($O13*CP13)/100)+(CQ13*12) | CU13: =(($O13*CS13)/100)+(CT13*12) | CX13: =(($O13*CV13)/100)+(CW13*12) | DA13: =(($O13*CY13)/100)+(CZ13*12) | DD13: =(($O13*DB13)/100)+(DC13*12) | DG13: =(($O13*DE13)/100)+(DF13*12) | DJ13: =(($O13*DH13)/100)+(DI13*12) | DM13: =(($O13*DK13)/100)+(DL13*12) | DP13: =(($O13*DN13)/100)+(DO13*12) | DS13: =(($O13*DQ13)/100)+(DR13*12) | DV13: =(($O13*DT13)/100)+(DU13*12)
B14: 74 | C14: 21/110 | D14: Communal Block,Penby Lawn | G14: Newnham on Severn | H14: UK | J14: 01-Jan-2027 | K14: 8 | L14: E6F11040652100 | M14: 4161533802 | N14: =IF(ISERROR(INDEX('Meter Type Data'!$B$2:$D$1165,SUMPRODUCT(--('Meter Type Data'!$B$2:$B$1165<=Analysis!L14)*('Meter Type Data'!$C$2:$C$1165>=Analysis!L14),ROW('Meter Type Data'!$B$2:$B$1165))-1,3))," ",INDEX('Meter Type Data'!$B$2:$D$1165,SUMPRODUCT(--('Meter Type Data'!$B$2:$B$1165<=Analysis!L14)*('Meter Type Data'!$C$2:$C$1165>=Analysis!L14),ROW('Meter Type Data'!$B$2:$B$1165))-1,3)) | P14: 8.407 | Q14: 8.407 | R14: 188.233 | U14: =(($O14*S14)/100)+(T14*12) | X14: =(($O14*V14)/100)+(W14*12) | AA14: =(($O14*Y14)/100)+(Z14*12) | AD14: =(($O14*AB14)/100)+(AC14*12) | AG14: =(($O14*AE14)/100)+(AF14*12) | AJ14: =(($O14*AH14)/100)+(AI14*12) | AM14: =(($O14*AK14)/100)+(AL14*12) | AP14: =(($O14*AN14)/100)+(AO14*12) | AS14: =(($O14*AQ14)/100)+(AR14*12) | AV14: =(($O14*AT14)/100)+(AU14*12) | AY14: =(($O14*AW14)/100)+(AX14*12) | BB14: =(($O14*AZ14)/100)+(BA14*12) | BE14: =(($O14*BC14)/100)+(BD14*12) | BH14: =(($O14*BF14)/100)+(BG14*12) | BK14: =(($O14*BI14)/100)+(BJ14*12) | BN14: =(($O14*BL14)/100)+(BM14*12) | BQ14: =(($O14*BO14)/100)+(BP14*12) | BT14: =(($O14*BR14)/100)+(BS14*12) | BW14: =(($O14*BU14)/100)+(BV14*12) | BZ14: =(($O14*BX14)/100)+(BY14*12) | CC14: =(($O14*CA14)/100)+(CB14*12) | CF14: =(($O14*CD14)/100)+(CE14*12) | CI14: =(($O14*CG14)/100)+(CH14*12) | CL14: =(($O14*CJ14)/100)+(CK14*12) | CO14: =(($O14*CM14)/100)+(CN14*12) | CR14: =(($O14*CP14)/100)+(CQ14*12) | CU14: =(($O14*CS14)/100)+(CT14*12)
B15: 79 | C15: 21/114 | D15: Tufton Close,Communal Block | G15: Coleford | H15: UK | J15: 01-Jan-2027 | K15: 8 | L15: 021309 | M15: 4168282704 | N15: =IF(ISERROR(INDEX('Meter Type Data'!$B$2:$D$1165,SUMPRODUCT(--('Meter Type Data'!$B$2:$B$1165<=Analysis!L15)*('Meter Type Data'!$C$2:$C$1165>=Analysis!L15),ROW('Meter Type Data'!$B$2:$B$1165))-1,3))," ",INDEX('Meter Type Data'!$B$2:$D$1165,SUMPRODUCT(--('Meter Type Data'!$B$2:$B$1165<=Analysis!L15)*('Meter Type Data'!$C$2:$C$1165>=Analysis!L15),ROW('Meter Type Data'!$B$2:$B$1165))-1,3)) | P15: 8.4091 | Q15: 8.4091 | R15: 149.924 | U15: =(($O15*S15)/100)+(T15*12) | X15: =(($O15*V15)/100)+(W15*12) | AA15: =(($O15*Y15)/100)+(Z15*12) | AD15: =(($O15*AB15)/100)+(AC15*12) | AG15: =(($O15*AE15)/100)+(AF15*12) | AJ15: =(($O15*AH15)/100)+(AI15*12) | AM15: =(($O15*AK15)/100)+(AL15*12) | AP15: =(($O15*AN15)/100)+(AO15*12) | AS15: =(($O15*AQ15)/100)+(AR15*12) | AV15: =(($O15*AT15)/100)+(AU15*12) | AY15: =(($O15*AW15)/100)+(AX15*12) | BB15: =(($O15*AZ15)/100)+(BA15*12) | BE15: =(($O15*BC15)/100)+(BD15*12) | BH15: =(($O15*BF15)/100)+(BG15*12) | BK15: =(($O15*BI15)/100)+(BJ15*12) | BN15: =(($O15*BL15)/100)+(BM15*12) | BQ15: =(($O15*BO15)/100)+(BP15*12) | BT15: =(($O15*BR15)/100)+(BS15*12) | BW15: =(($O15*BU15)/100)+(BV15*12) | BZ15: =(($O15*BX15)/100)+(BY15*12) | CC15: =(($O15*CA15)/100)+(CB15*12) | CF15: =(($O15*CD15)/100)+(CE15*12) | CI15: =(($O15*CG15)/100)+(CH15*12) | CL15: =(($O15*CJ15)/100)+(CK15*12) | CO15: =(($O15*CM15)/100)+(CN15*12) | CR15: =(($O15*CP15)/100)+(CQ15*12) | CU15: =(($O15*CS15)/100)+(CT15*12)
B16: 81 | C16: 21/117 | D16: Community Centre,Worcester Road | G16: Cinderford | H16: UK | J16: 01-Jan-2027 | K16: 8 | L16: 088757 | M16: 4168058800 | N16: =IF(ISERROR(INDEX('Meter Type Data'!$B$2:$D$1165,SUMPRODUCT(--('Meter Type Data'!$B$2:$B$1165<=Analysis!L16)*('Meter Type Data'!$C$2:$C$1165>=Analysis!L16),ROW('Meter Type Data'!$B$2:$B$1165))-1,3))," ",INDEX('Meter Type Data'!$B$2:$D$1165,SUMPRODUCT(--('Meter Type Data'!$B$2:$B$1165<=Analysis!L16)*('Meter Type Data'!$C$2:$C$1165>=Analysis!L16),ROW('Meter Type Data'!$B$2:$B$1165))-1,3)) | P16: 8.4136 | Q16: 8.4136 | R16: 93.6213 | U16: =(($O16*S16)/100)+(T16*12) | X16: =(($O16*V16)/100)+(W16*12) | AA16: =(($O16*Y16)/100)+(Z16*12) | AD16: =(($O16*AB16)/100)+(AC16*12) | AG16: =(($O16*AE16)/100)+(AF16*12) | AJ16: =(($O16*AH16)/100)+(AI16*12) | AM16: =(($O16*AK16)/100)+(AL16*12) | AP16: =(($O16*AN16)/100)+(AO16*12) | AS16: =(($O16*AQ16)/100)+(AR16*12) | AV16: =(($O16*AT16)/100)+(AU16*12) | AY16: =(($O16*AW16)/100)+(AX16*12) | BB16: =(($O16*AZ16)/100)+(BA16*12) | BE16: =(($O16*BC16)/100)+(BD16*12) | BH16: =(($O16*BF16)/100)+(BG16*12) | BK16: =(($O16*BI16)/100)+(BJ16*12) | BN16: =(($O16*BL16)/100)+(BM16*12) | BQ16: =(($O16*BO16)/100)+(BP16*12) | BT16: =(($O16*BR16)/100)+(BS16*12) | BW16: =(($O16*BU16)/100)+(BV16*12) | BZ16: =(($O16*BX16)/100)+(BY16*12) | CC16: =(($O16*CA16)/100)+(CB16*12) | CF16: =(($O16*CD16)/100)+(CE16*12) | CI16: =(($O16*CG16)/100)+(CH16*12) | CL16: =(($O16*CJ16)/100)+(CK16*12) | CO16: =(($O16*CM16)/100)+(CN16*12) | CR16: =(($O16*CP16)/100)+(CQ16*12) | CU16: =(($O16*CS16)/100)+(CT16*12)
B17: 82 | C17: 21/116 | D17: 18 Willowdean,Communal Block | G17: Cinderford | H17: UK | J17: 01-Jan-2027 | K17: 8 | L17: G4K00062491101 | M17: 9314454307 | N17: =IF(ISERROR(INDEX('Meter Type Data'!$B$2:$D$1165,SUMPRODUCT(--('Meter Type Data'!$B$2:$B$1165<=Analysis!L17)*('Meter Type Data'!$C$2:$C$1165>=Analysis!L17),ROW('Meter Type Data'!$B$2:$B$1165))-1,3))," ",INDEX('Meter Type Data'!$B$2:$D$1165,SUMPRODUCT(--('Meter Type Data'!$B$2:$B$1165<=Analysis!L17)*('Meter Type Data'!$C$2:$C$1165>=Analysis!L17),ROW('Meter Type Data'!$B$2:$B$1165))-1,3)) | P17: 8.4069 | Q17: 8.4069 | R17: 271.0118 | U17: =(($O17*S17)/100)+(T17*12) | X17: =(($O17*V17)/100)+(W17*12) | AA17: =(($O17*Y17)/100)+(Z17*12) | AD17: =(($O17*AB17)/100)+(AC17*12) | AG17: =(($O17*AE17)/100)+(AF17*12) | AJ17: =(($O17*AH17)/100)+(AI17*12) | AM17: =(($O17*AK17)/100)+(AL17*12) | AP17: =(($O17*AN17)/100)+(AO17*12) | AS17: =(($O17*AQ17)/100)+(AR17*12) | AV17: =(($O17*AT17)/100)+(AU17*12) | AY17: =(($O17*AW17)/100)+(AX17*12) | BB17: =(($O17*AZ17)/100)+(BA17*12) | BE17: =(($O17*BC17)/100)+(BD17*12) | BH17: =(($O17*BF17)/100)+(BG17*12) | BK17: =(($O17*BI17)/100)+(BJ17*12) | BN17: =(($O17*BL17)/100)+(BM17*12) | BQ17: =(($O17*BO17)/100)+(BP17*12) | BT17: =(($O17*BR17)/100)+(BS17*12) | BW17: =(($O17*BU17)/100)+(BV17*12) | BZ17: =(($O17*BX17)/100)+(BY17*12) | CC17: =(($O17*CA17)/100)+(CB17*12) | CF17: =(($O17*CD17)/100)+(CE17*12) | CI17: =(($O17*CG17)/100)+(CH17*12) | CL17: =(($O17*CJ17)/100)+(CK17*12) | CO17: =(($O17*CM17)/100)+(CN17*12) | CR17: =(($O17*CP17)/100)+(CQ17*12) | CU17: =(($O17*CS17)/100)+(CT17*12)
B18: 83 | C18: 21/118 | D18: Wynols Close,Community Centre | G18: Coleford | H18: UK | J18: 01-Jan-2027 | K18: 8 | L18: E6F11073502100 | M18: 4166534605 | N18: =IF(ISERROR(INDEX('Meter Type Data'!$B$2:$D$1165,SUMPRODUCT(--('Meter Type Data'!$B$2:$B$1165<=Analysis!L18)*('Meter Type Data'!$C$2:$C$1165>=Analysis!L18),ROW('Meter Type Data'!$B$2:$B$1165))-1,3))," ",INDEX('Meter Type Data'!$B$2:$D$1165,SUMPRODUCT(--('Meter Type Data'!$B$2:$B$1165<=Analysis!L18)*('Meter Type Data'!$C$2:$C$1165>=Analysis!L18),ROW('Meter Type Data'!$B$2:$B$1165))-1,3)) | P18: 8.41 | Q18: 8.41 | R18: 105.8106 | U18: =(($O18*S18)/100)+(T18*12) | X18: =(($O18*V18)/100)+(W18*12) | AA18: =(($O18*Y18)/100)+(Z18*12) | AD18: =(($O18*AB18)/100)+(AC18*12) | AG18: =(($O18*AE18)/100)+(AF18*12) | AJ18: =(($O18*AH18)/100)+(AI18*12) | AM18: =(($O18*AK18)/100)+(AL18*12) | AP18: =(($O18*AN18)/100)+(AO18*12) | AS18: =(($O18*AQ18)/100)+(AR18*12) | AV18: =(($O18*AT18)/100)+(AU18*12) | AY18: =(($O18*AW18)/100)+(AX18*12) | BB18: =(($O18*AZ18)/100)+(BA18*12) | BE18: =(($O18*BC18)/100)+(BD18*12) | BH18: =(($O18*BF18)/100)+(BG18*12) | BK18: =(($O18*BI18)/100)+(BJ18*12) | BN18: =(($O18*BL18)/100)+(BM18*12) | BQ18: =(($O18*BO18)/100)+(BP18*12) | BT18: =(($O18*BR18)/100)+(BS18*12) | BW18: =(($O18*BU18)/100)+(BV18*12) | BZ18: =(($O18*BX18)/100)+(BY18*12) | CC18: =(($O18*CA18)/100)+(CB18*12) | CF18: =(($O18*CD18)/100)+(CE18*12) | CI18: =(($O18*CG18)/100)+(CH18*12) | CL18: =(($O18*CJ18)/100)+(CK18*12) | CO18: =(($O18*CM18)/100)+(CN18*12) | CR18: =(($O18*CP18)/100)+(CQ18*12) | CU18: =(($O18*CS18)/100)+(CT18*12)
B19: 87 | C19: 21/122 | D19: Rowandean,Communal Centre | G19: Cinderford | H19: UK | J19: 01-Jan-2027 | K19: 8 | L19: E6E01299742110 | M19: 4166990710 | N19: =IF(ISERROR(INDEX('Meter Type Data'!$B$2:$D$1165,SUMPRODUCT(--('Meter Type Data'!$B$2:$B$1165<=Analysis!L19)*('Meter Type Data'!$C$2:$C$1165>=Analysis!L19),ROW('Meter Type Data'!$B$2:$B$1165))-1,3))," ",INDEX('Meter Type Data'!$B$2:$D$1165,SUMPRODUCT(--('Meter Type Data'!$B$2:$B$1165<=Analysis!L19)*('Meter Type Data'!$C$2:$C$1165>=Analysis!L19),ROW('Meter Type Data'!$B$2:$B$1165))-1,3)) | P19: 8.4076 | Q19: 8.4076 | R19: 173.1415 | U19: =(($O19*S19)/100)+(T19*12) | X19: =(($O19*V19)/100)+(W19*12) | AA19: =(($O19*Y19)/100)+(Z19*12) | AD19: =(($O19*AB19)/100)+(AC19*12) | AG19: =(($O19*AE19)/100)+(AF19*12) | AJ19: =(($O19*AH19)/100)+(AI19*12) | AM19: =(($O19*AK19)/100)+(AL19*12) | AP19: =(($O19*AN19)/100)+(AO19*12) | AS19: =(($O19*AQ19)/100)+(AR19*12) | AV19: =(($O19*AT19)/100)+(AU19*12) | AY19: =(($O19*AW19)/100)+(AX19*12) | BB19: =(($O19*AZ19)/100)+(BA19*12) | BE19: =(($O19*BC19)/100)+(BD19*12) | BH19: =(($O19*BF19)/100)+(BG19*12) | BK19: =(($O19*BI19)/100)+(BJ19*12) | BN19: =(($O19*BL19)/100)+(BM19*12) | BQ19: =(($O19*BO19)/100)+(BP19*12) | BT19: =(($O19*BR19)/100)+(BS19*12) | BW19: =(($O19*BU19)/100)+(BV19*12) | BZ19: =(($O19*BX19)/100)+(BY19*12) | CC19: =(($O19*CA19)/100)+(CB19*12) | CF19: =(($O19*CD19)/100)+(CE19*12) | CI19: =(($O19*CG19)/100)+(CH19*12) | CL19: =(($O19*CJ19)/100)+(CK19*12) | CO19: =(($O19*CM19)/100)+(CN19*12) | CR19: =(($O19*CP19)/100)+(CQ19*12) | CU19: =(($O19*CS19)/100)+(CT19*12)
B20: 88 | C20: 21/119 | D20: The Flats,Spring Meadow | G20: Gloucester | H20: UK | J20: 01-Jan-2027 | K20: 8 | L20: 0126553 | M20: 4166087101 | N20: =IF(ISERROR(INDEX('Meter Type Data'!$B$2:$D$1165,SUMPRODUCT(--('Meter Type Data'!$B$2:$B$1165<=Analysis!L20)*('Meter Type Data'!$C$2:$C$1165>=Analysis!L20),ROW('Meter Type Data'!$B$2:$B$1165))-1,3))," ",INDEX('Meter Type Data'!$B$2:$D$1165,SUMPRODUCT(--('Meter Type Data'!$B$2:$B$1165<=Analysis!L20)*('Meter Type Data'!$C$2:$C$1165>=Analysis!L20),ROW('Meter Type Data'!$B$2:$B$1165))-1,3)) | P20: 8.469 | Q20: 8.469 | R20: 463.3612 | U20: =(($O20*S20)/100)+(T20*12) | X20: =(($O20*V20)/100)+(W20*12) | AA20: =(($O20*Y20)/100)+(Z20*12) | AD20: =(($O20*AB20)/100)+(AC20*12) | AG20: =(($O20*AE20)/100)+(AF20*12) | AJ20: =(($O20*AH20)/100)+(AI20*12) | AM20: =(($O20*AK20)/100)+(AL20*12) | AP20: =(($O20*AN20)/100)+(AO20*12) | AS20: =(($O20*AQ20)/100)+(AR20*12) | AV20: =(($O20*AT20)/100)+(AU20*12) | AY20: =(($O20*AW20)/100)+(AX20*12) | BB20: =(($O20*AZ20)/100)+(BA20*12) | BE20: =(($O20*BC20)/100)+(BD20*12) | BH20: =(($O20*BF20)/100)+(BG20*12) | BK20: =(($O20*BI20)/100)+(BJ20*12) | BN20: =(($O20*BL20)/100)+(BM20*12) | BQ20: =(($O20*BO20)/100)+(BP20*12) | BT20: =(($O20*BR20)/100)+(BS20*12) | BW20: =(($O20*BU20)/100)+(BV20*12) | BZ20: =(($O20*BX20)/100)+(BY20*12) | CC20: =(($O20*CA20)/100)+(CB20*12) | CF20: =(($O20*CD20)/100)+(CE20*12) | CI20: =(($O20*CG20)/100)+(CH20*12) | CL20: =(($O20*CJ20)/100)+(CK20*12) | CO20: =(($O20*CM20)/100)+(CN20*12) | CR20: =(($O20*CP20)/100)+(CQ20*12) | CU20: =(($O20*CS20)/100)+(CT20*12)
B21: 94 | C21: 21/119 | D21: Communal Centre, 5 Watermead,The Springs | G21: Gloucester | H21: UK | J21: 01-Jan-2027 | K21: 8 | L21: G4F00405392000 | M21: 4168676804 | N21: =IF(ISERROR(INDEX('Meter Type Data'!$B$2:$D$1165,SUMPRODUCT(--('Meter Type Data'!$B$2:$B$1165<=Analysis!L21)*('Meter Type Data'!$C$2:$C$1165>=Analysis!L21),ROW('Meter Type Data'!$B$2:$B$1165))-1,3))," ",INDEX('Meter Type Data'!$B$2:$D$1165,SUMPRODUCT(--('Meter Type Data'!$B$2:$B$1165<=Analysis!L21)*('Meter Type Data'!$C$2:$C$1165>=Analysis!L21),ROW('Meter Type Data'!$B$2:$B$1165))-1,3)) | P21: 8.4091 | Q21: 8.4091 | R21: 88.3974 | U21: =(($O21*S21)/100)+(T21*12) | X21: =(($O21*V21)/100)+(W21*12) | AA21: =(($O21*Y21)/100)+(Z21*12) | AD21: =(($O21*AB21)/100)+(AC21*12) | AG21: =(($O21*AE21)/100)+(AF21*12) | AJ21: =(($O21*AH21)/100)+(AI21*12) | AM21: =(($O21*AK21)/100)+(AL21*12) | AP21: =(($O21*AN21)/100)+(AO21*12) | AS21: =(($O21*AQ21)/100)+(AR21*12) | AV21: =(($O21*AT21)/100)+(AU21*12) | AY21: =(($O21*AW21)/100)+(AX21*12) | BB21: =(($O21*AZ21)/100)+(BA21*12) | BE21: =(($O21*BC21)/100)+(BD21*12) | BH21: =(($O21*BF21)/100)+(BG21*12) | BK21: =(($O21*BI21)/100)+(BJ21*12) | BN21: =(($O21*BL21)/100)+(BM21*12) | BQ21: =(($O21*BO21)/100)+(BP21*12) | BT21: =(($O21*BR21)/100)+(BS21*12) | BW21: =(($O21*BU21)/100)+(BV21*12) | BZ21: =(($O21*BX21)/100)+(BY21*12) | CC21: =(($O21*CA21)/100)+(CB21*12) | CF21: =(($O21*CD21)/100)+(CE21*12) | CI21: =(($O21*CG21)/100)+(CH21*12) | CL21: =(($O21*CJ21)/100)+(CK21*12) | CO21: =(($O21*CM21)/100)+(CN21*12) | CR21: =(($O21*CP21)/100)+(CQ21*12) | CU21: =(($O21*CS21)/100)+(CT21*12)
B22: 96 | C22: 21/113 | D22: 7 The Horsepool,Berry Hill | G22: Coleford | H22: UK | J22: 01-Jan-2027 | K22: 8 | L22: E6F13159132100 | M22: 4161545607 | N22: =IF(ISERROR(INDEX('Meter Type Data'!$B$2:$D$1165,SUMPRODUCT(--('Meter Type Data'!$B$2:$B$1165<=Analysis!L22)*('Meter Type Data'!$C$2:$C$1165>=Analysis!L22),ROW('Meter Type Data'!$B$2:$B$1165))-1,3))," ",INDEX('Meter Type Data'!$B$2:$D$1165,SUMPRODUCT(--('Meter Type Data'!$B$2:$B$1165<=Analysis!L22)*('Meter Type Data'!$C$2:$C$1165>=Analysis!L22),ROW('Meter Type Data'!$B$2:$B$1165))-1,3)) | P22: 8.4074 | Q22: 8.4074 | R22: 140.0565 | U22: =(($O22*S22)/100)+(T22*12) | X22: =(($O22*V22)/100)+(W22*12) | AA22: =(($O22*Y22)/100)+(Z22*12) | AD22: =(($O22*AB22)/100)+(AC22*12) | AG22: =(($O22*AE22)/100)+(AF22*12) | AJ22: =(($O22*AH22)/100)+(AI22*12) | AM22: =(($O22*AK22)/100)+(AL22*12) | AP22: =(($O22*AN22)/100)+(AO22*12) | AS22: =(($O22*AQ22)/100)+(AR22*12) | AV22: =(($O22*AT22)/100)+(AU22*12) | AY22: =(($O22*AW22)/100)+(AX22*12) | BB22: =(($O22*AZ22)/100)+(BA22*12) | BE22: =(($O22*BC22)/100)+(BD22*12) | BH22: =(($O22*BF22)/100)+(BG22*12) | BK22: =(($O22*BI22)/100)+(BJ22*12) | BN22: =(($O22*BL22)/100)+(BM22*12) | BQ22: =(($O22*BO22)/100)+(BP22*12) | BT22: =(($O22*BR22)/100)+(BS22*12) | BW22: =(($O22*BU22)/100)+(BV22*12) | BZ22: =(($O22*BX22)/100)+(BY22*12) | CC22: =(($O22*CA22)/100)+(CB22*12) | CF22: =(($O22*CD22)/100)+(CE22*12) | CI22: =(($O22*CG22)/100)+(CH22*12) | CL22: =(($O22*CJ22)/100)+(CK22*12) | CO22: =(($O22*CM22)/100)+(CN22*12) | CR22: =(($O22*CP22)/100)+(CQ22*12) | CU22: =(($O22*CS22)/100)+(CT22*12)
B23: 97 | C23: 21/108 | D23: Communal Block,Meads Close | G23: Coleford | H23: UK | J23: 01-Jan-2027 | K23: 8 | L23: E6F11113552100 | M23: 4166336208 | N23: =IF(ISERROR(INDEX('Meter Type Data'!$B$2:$D$1165,SUMPRODUCT(--('Meter Type Data'!$B$2:$B$1165<=Analysis!L23)*('Meter Type Data'!$C$2:$C$1165>=Analysis!L23),ROW('Meter Type Data'!$B$2:$B$1165))-1,3))," ",INDEX('Meter Type Data'!$B$2:$D$1165,SUMPRODUCT(--('Meter Type Data'!$B$2:$B$1165<=Analysis!L23)*('Meter Type Data'!$C$2:$C$1165>=Analysis!L23),ROW('Meter Type Data'!$B$2:$B$1165))-1,3)) | P23: 8.4128 | Q23: 8.4128 | R23: 118.5802 | U23: =(($O23*S23)/100)+(T23*12) | X23: =(($O23*V23)/100)+(W23*12) | AA23: =(($O23*Y23)/100)+(Z23*12) | AD23: =(($O23*AB23)/100)+(AC23*12) | AG23: =(($O23*AE23)/100)+(AF23*12) | AJ23: =(($O23*AH23)/100)+(AI23*12) | AM23: =(($O23*AK23)/100)+(AL23*12) | AP23: =(($O23*AN23)/100)+(AO23*12) | AS23: =(($O23*AQ23)/100)+(AR23*12) | AV23: =(($O23*AT23)/100)+(AU23*12) | AY23: =(($O23*AW23)/100)+(AX23*12) | BB23: =(($O23*AZ23)/100)+(BA23*12) | BE23: =(($O23*BC23)/100)+(BD23*12) | BH23: =(($O23*BF23)/100)+(BG23*12) | BK23: =(($O23*BI23)/100)+(BJ23*12) | BN23: =(($O23*BL23)/100)+(BM23*12) | BQ23: =(($O23*BO23)/100)+(BP23*12) | BT23: =(($O23*BR23)/100)+(BS23*12) | BW23: =(($O23*BU23)/100)+(BV23*12) | BZ23: =(($O23*BX23)/100)+(BY23*12) | CC23: =(($O23*CA23)/100)+(CB23*12) | CF23: =(($O23*CD23)/100)+(CE23*12) | CI23: =(($O23*CG23)/100)+(CH23*12) | CL23: =(($O23*CJ23)/100)+(CK23*12) | CO23: =(($O23*CM23)/100)+(CN23*12) | CR23: =(($O23*CP23)/100)+(CQ23*12) | CU23: =(($O23*CS23)/100)+(CT23*12)
B24: 98 | C24: 21/112 | D24: Church Street,St Batholemews | G24: Newent | H24: UK | J24: 01-Jan-2027 | K24: 8 | L24: M025A0316108A6 | M24: 4161405400 | N24: =IF(ISERROR(INDEX('Meter Type Data'!$B$2:$D$1165,SUMPRODUCT(--('Meter Type Data'!$B$2:$B$1165<=Analysis!L24)*('Meter Type Data'!$C$2:$C$1165>=Analysis!L24),ROW('Meter Type Data'!$B$2:$B$1165))-1,3))," ",INDEX('Meter Type Data'!$B$2:$D$1165,SUMPRODUCT(--('Meter Type Data'!$B$2:$B$1165<=Analysis!L24)*('Meter Type Data'!$C$2:$C$1165>=Analysis!L24),ROW('Meter Type Data'!$B$2:$B$1165))-1,3)) | P24: 8.4103 | Q24: 8.4103 | R24: 201.5831 | U24: =(($O24*S24)/100)+(T24*12) | X24: =(($O24*V24)/100)+(W24*12) | AA24: =(($O24*Y24)/100)+(Z24*12) | AD24: =(($O24*AB24)/100)+(AC24*12) | AG24: =(($O24*AE24)/100)+(AF24*12) | AJ24: =(($O24*AH24)/100)+(AI24*12) | AM24: =(($O24*AK24)/100)+(AL24*12) | AP24: =(($O24*AN24)/100)+(AO24*12) | AS24: =(($O24*AQ24)/100)+(AR24*12) | AV24: =(($O24*AT24)/100)+(AU24*12) | AY24: =(($O24*AW24)/100)+(AX24*12) | BB24: =(($O24*AZ24)/100)+(BA24*12) | BE24: =(($O24*BC24)/100)+(BD24*12) | BH24: =(($O24*BF24)/100)+(BG24*12) | BK24: =(($O24*BI24)/100)+(BJ24*12) | BN24: =(($O24*BL24)/100)+(BM24*12) | BQ24: =(($O24*BO24)/100)+(BP24*12) | BT24: =(($O24*BR24)/100)+(BS24*12) | BW24: =(($O24*BU24)/100)+(BV24*12) | BZ24: =(($O24*BX24)/100)+(BY24*12) | CC24: =(($O24*CA24)/100)+(CB24*12) | CF24: =(($O24*CD24)/100)+(CE24*12) | CI24: =(($O24*CG24)/100)+(CH24*12) | CL24: =(($O24*CJ24)/100)+(CK24*12) | CO24: =(($O24*CM24)/100)+(CN24*12) | CR24: =(($O24*CP24)/100)+(CQ24*12) | CU24: =(($O24*CS24)/100)+(CT24*12)
B25: 99 | C25: 21/106 | D25: Communal Centre,Hillcrest Road | G25: Coleford | H25: UK | J25: 01-Jan-2027 | K25: 8 | L25: E6E05991252221 | M25: 4155788008 | N25: =IF(ISERROR(INDEX('Meter Type Data'!$B$2:$D$1165,SUMPRODUCT(--('Meter Type Data'!$B$2:$B$1165<=Analysis!L25)*('Meter Type Data'!$C$2:$C$1165>=Analysis!L25),ROW('Meter Type Data'!$B$2:$B$1165))-1,3))," ",INDEX('Meter Type Data'!$B$2:$D$1165,SUMPRODUCT(--('Meter Type Data'!$B$2:$B$1165<=Analysis!L25)*('Meter Type Data'!$C$2:$C$1165>=Analysis!L25),ROW('Meter Type Data'!$B$2:$B$1165))-1,3)) | P25: 8.4113 | Q25: 8.4113 | R25: 95.3627 | U25: =(($O25*S25)/100)+(T25*12) | X25: =(($O25*V25)/100)+(W25*12) | AA25: =(($O25*Y25)/100)+(Z25*12) | AD25: =(($O25*AB25)/100)+(AC25*12) | AG25: =(($O25*AE25)/100)+(AF25*12) | AJ25: =(($O25*AH25)/100)+(AI25*12) | AM25: =(($O25*AK25)/100)+(AL25*12) | AP25: =(($O25*AN25)/100)+(AO25*12) | AS25: =(($O25*AQ25)/100)+(AR25*12) | AV25: =(($O25*AT25)/100)+(AU25*12) | AY25: =(($O25*AW25)/100)+(AX25*12) | BB25: =(($O25*AZ25)/100)+(BA25*12) | BE25: =(($O25*BC25)/100)+(BD25*12) | BH25: =(($O25*BF25)/100)+(BG25*12) | BK25: =(($O25*BI25)/100)+(BJ25*12) | BN25: =(($O25*BL25)/100)+(BM25*12) | BQ25: =(($O25*BO25)/100)+(BP25*12) | BT25: =(($O25*BR25)/100)+(BS25*12) | BW25: =(($O25*BU25)/100)+(BV25*12) | BZ25: =(($O25*BX25)/100)+(BY25*12) | CC25: =(($O25*CA25)/100)+(CB25*12) | CF25: =(($O25*CD25)/100)+(CE25*12) | CI25: =(($O25*CG25)/100)+(CH25*12) | CL25: =(($O25*CJ25)/100)+(CK25*12) | CO25: =(($O25*CM25)/100)+(CN25*12) | CR25: =(($O25*CP25)/100)+(CQ25*12) | CU25: =(($O25*CS25)/100)+(CT25*12)
... B27: 101 | C27: 21/101 | D27: Communal Block ,Sheltered Housing | G27: Chepstow | H27: UK | J27: 01-Jan-2027 | K27: 8 | L27: 7315411S | M27: 2782909304 | N27: =IF(ISERROR(INDEX('Meter Type Data'!$B$2:$D$1165,SUMPRODUCT(--('Meter Type Data'!$B$2:$B$1165<=Analysis!L27)*('Meter Type Data'!$C$2:$C$1165>=Analysis!L27),ROW('Meter Type Data'!$B$2:$B$1165))-1,3))," ",INDEX('Meter Type Data'!$B$2:$D$1165,SUMPRODUCT(--('Meter Type Data'!$B$2:$B$1165<=Analysis!L27)*('Meter Type Data'!$C$2:$C$1165>=Analysis!L27),ROW('Meter Type Data'!$B$2:$B$1165))-1,3)) | P27: 8.4645 | Q27: 8.4645 | R27: 53.355 | U27: =(($O27*S27)/100)+(T27*12) | X27: =(($O27*V27)/100)+(W27*12) | AA27: =(($O27*Y27)/100)+(Z27*12) | AD27: =(($O27*AB27)/100)+(AC27*12) | AG27: =(($O27*AE27)/100)+(AF27*12) | AJ27: =(($O27*AH27)/100)+(AI27*12) | AM27: =(($O27*AK27)/100)+(AL27*12) | AP27: =(($O27*AN27)/100)+(AO27*12) | AS27: =(($O27*AQ27)/100)+(AR27*12) | AV27: =(($O27*AT27)/100)+(AU27*12) | AY27: =(($O27*AW27)/100)+(AX27*12) | BB27: =(($O27*AZ27)/100)+(BA27*12) | BE27: =(($O27*BC27)/100)+(BD27*12) | BH27: =(($O27*BF27)/100)+(BG27*12) | BK27: =(($O27*BI27)/100)+(BJ27*12) | BN27: =(($O27*BL27)/100)+(BM27*12) | BQ27: =(($O27*BO27)/100)+(BP27*12) | BT27: =(($O27*BR27)/100)+(BS27*12) | BW27: =(($O27*BU27)/100)+(BV27*12) | BZ27: =(($O27*BX27)/100)+(BY27*12) | CC27: =(($O27*CA27)/100)+(CB27*12) | CF27: =(($O27*CD27)/100)+(CE27*12) | CI27: =(($O27*CG27)/100)+(CH27*12) | CL27: =(($O27*CJ27)/100)+(CK27*12) | CO27: =(($O27*CM27)/100)+(CN27*12) | CR27: =(($O27*CP27)/100)+(CQ27*12) | CU27: =(($O27*CS27)/100)+(CT27*12)
B28: 155 | D28: Flats Adjacent to 9 Wellington Street | G28: Gloucester | H28: UK | J28: 01-Jan-2027 | K28: 8 | L28: M040A0069313D6 | M28: 9354618302 | N28: =IF(ISERROR(INDEX('Meter Type Data'!$B$2:$D$1165,SUMPRODUCT(--('Meter Type Data'!$B$2:$B$1165<=Analysis!L28)*('Meter Type Data'!$C$2:$C$1165>=Analysis!L28),ROW('Meter Type Data'!$B$2:$B$1165))-1,3))," ",INDEX('Meter Type Data'!$B$2:$D$1165,SUMPRODUCT(--('Meter Type Data'!$B$2:$B$1165<=Analysis!L28)*('Meter Type Data'!$C$2:$C$1165>=Analysis!L28),ROW('Meter Type Data'!$B$2:$B$1165))-1,3)) | P28: 8.4222 | Q28: 8.4222 | R28: 75.6277 | U28: =(($O28*S28)/100)+(T28*12) | X28: =(($O28*V28)/100)+(W28*12) | AA28: =(($O28*Y28)/100)+(Z28*12) | AD28: =(($O28*AB28)/100)+(AC28*12) | AG28: =(($O28*AE28)/100)+(AF28*12) | AJ28: =(($O28*AH28)/100)+(AI28*12) | AM28: =(($O28*AK28)/100)+(AL28*12) | AP28: =(($O28*AN28)/100)+(AO28*12) | AS28: =(($O28*AQ28)/100)+(AR28*12) | AV28: =(($O28*AT28)/100)+(AU28*12) | AY28: =(($O28*AW28)/100)+(AX28*12) | BB28: =(($O28*AZ28)/100)+(BA28*12) | BE28: =(($O28*BC28)/100)+(BD28*12) | BH28: =(($O28*BF28)/100)+(BG28*12) | BK28: =(($O28*BI28)/100)+(BJ28*12) | BN28: =(($O28*BL28)/100)+(BM28*12) | BQ28: =(($O28*BO28)/100)+(BP28*12) | BT28: =(($O28*BR28)/100)+(BS28*12) | BW28: =(($O28*BU28)/100)+(BV28*12) | BZ28: =(($O28*BX28)/100)+(BY28*12) | CC28: =(($O28*CA28)/100)+(CB28*12) | CF28: =(($O28*CD28)/100)+(CE28*12) | CI28: =(($O28*CG28)/100)+(CH28*12) | CL28: =(($O28*CJ28)/100)+(CK28*12) | CO28: =(($O28*CM28)/100)+(CN28*12) | CR28: =(($O28*CP28)/100)+(CQ28*12) | CU28: =(($O28*CS28)/100)+(CT28*12)
B29: 176 | D29: 15 King Alfreds Road,Sedbury | G29: Chepstow | H29: UK | J29: 01-Jan-2027 | K29: 8 | L29: M016A1060012A6 | M29: 46302408 | N29: =IF(ISERROR(INDEX('Meter Type Data'!$B$2:$D$1165,SUMPRODUCT(--('Meter Type Data'!$B$2:$B$1165<=Analysis!L29)*('Meter Type Data'!$C$2:$C$1165>=Analysis!L29),ROW('Meter Type Data'!$B$2:$B$1165))-1,3))," ",INDEX('Meter Type Data'!$B$2:$D$1165,SUMPRODUCT(--('Meter Type Data'!$B$2:$B$1165<=Analysis!L29)*('Meter Type Data'!$C$2:$C$1165>=Analysis!L29),ROW('Meter Type Data'!$B$2:$B$1165))-1,3)) | P29: 7.5618 | Q29: 7.5618 | R29: 633.8842 | U29: =(($O29*S29)/100)+(T29*12) | X29: =(($O29*V29)/100)+(W29*12) | AA29: =(($O29*Y29)/100)+(Z29*12) | AD29: =(($O29*AB29)/100)+(AC29*12) | AG29: =(($O29*AE29)/100)+(AF29*12) | AJ29: =(($O29*AH29)/100)+(AI29*12) | AM29: =(($O29*AK29)/100)+(AL29*12) | AP29: =(($O29*AN29)/100)+(AO29*12) | AS29: =(($O29*AQ29)/100)+(AR29*12) | AV29: =(($O29*AT29)/100)+(AU29*12) | AY29: =(($O29*AW29)/100)+(AX29*12) | BB29: =(($O29*AZ29)/100)+(BA29*12) | BE29: =(($O29*BC29)/100)+(BD29*12) | BH29: =(($O29*BF29)/100)+(BG29*12) | BK29: =(($O29*BI29)/100)+(BJ29*12) | BN29: =(($O29*BL29)/100)+(BM29*12) | BQ29: =(($O29*BO29)/100)+(BP29*12) | BT29: =(($O29*BR29)/100)+(BS29*12) | BW29: =(($O29*BU29)/100)+(BV29*12) | BZ29: =(($O29*BX29)/100)+(BY29*12) | CC29: =(($O29*CA29)/100)+(CB29*12) | CF29: =(($O29*CD29)/100)+(CE29*12) | CI29: =(($O29*CG29)/100)+(CH29*12) | CL29: =(($O29*CJ29)/100)+(CK29*12) | CO29: =(($O29*CM29)/100)+(CN29*12) | CR29: =(($O29*CP29)/100)+(CQ29*12) | CU29: =(($O29*CS29)/100)+(CT29*12)
M30: =IF(ISERROR(INDEX('Meter Type Data'!$B$2:$E$1165,SUMPRODUCT(--('Meter Type Data'!$B$2:$B$1165<=Analysis!L30)*('Meter Type Data'!$C$2:$C$1165>=Analysis!L30),ROW('Meter Type Data'!$B$2:$B$1165))-1,4))," ",INDEX('Meter Type Data'!$B$2:$E$1165,SUMPRODUCT(--('Meter Type Data'!$B$2:$B$1165<=Analysis!L30)*('Meter Type Data'!$C$2:$C$1165>=Analysis!L30),ROW('Meter Type Data'!$B$2:$B$1165))-1,4)) | N30: =IF(ISERROR(INDEX('Meter Type Data'!$B$2:$D$1165,SUMPRODUCT(--('Meter Type Data'!$B$2:$B$1165<=Analysis!L30)*('Meter Type Data'!$C$2:$C$1165>=Analysis!L30),ROW('Meter Type Data'!$B$2:$B$1165))-1,3))," ",INDEX('Meter Type Data'!$B$2:$D$1165,SUMPRODUCT(--('Meter Type Data'!$B$2:$B$1165<=Analysis!L30)*('Meter Type Data'!$C$2:$C$1165>=Analysis!L30),ROW('Meter Type Data'!$B$2:$B$1165))-1,3)) | R30: =(($O30*P30)/100)+(Q30*12) | U30: =(($O30*S30)/100)+(T30*12) | X30: =(($O30*V30)/100)+(W30*12) | AA30: =(($O30*Y30)/100)+(Z30*12) | AD30: =(($O30*AB30)/100)+(AC30*12) | AG30: =(($O30*AE30)/100)+(AF30*12) | AJ30: =(($O30*AH30)/100)+(AI30*12) | AM30: =(($O30*AK30)/100)+(AL30*12) | AP30: =(($O30*AN30)/100)+(AO30*12) | AS30: =(($O30*AQ30)/100)+(AR30*12) | AV30: =(($O30*AT30)/100)+(AU30*12) | AY30: =(($O30*AW30)/100)+(AX30*12) | BB30: =(($O30*AZ30)/100)+(BA30*12) | BE30: =(($O30*BC30)/100)+(BD30*12) | BH30: =(($O30*BF30)/100)+(BG30*12) | BK30: =(($O30*BI30)/100)+(BJ30*12) | BN30: =(($O30*BL30)/100)+(BM30*12) | BQ30: =(($O30*BO30)/100)+(BP30*12) | BT30: =(($O30*BR30)/100)+(BS30*12) | BW30: =(($O30*BU30)/100)+(BV30*12) | BZ30: =(($O30*BX30)/100)+(BY30*12) | CC30: =(($O30*CA30)/100)+(CB30*12) | CF30: =(($O30*CD30)/100)+(CE30*12) | CI30: =(($O30*CG30)/100)+(CH30*12) | CL30: =(($O30*CJ30)/100)+(CK30*12) | CO30: =(($O30*CM30)/100)+(CN30*12) | CR30: =(($O30*CP30)/100)+(CQ30*12) | CU30: =(($O30*CS30)/100)+(CT30*12)
M31: =IF(ISERROR(INDEX('Meter Type Data'!$B$2:$E$1165,SUMPRODUCT(--('Meter Type Data'!$B$2:$B$1165<=Analysis!L31)*('Meter Type Data'!$C$2:$C$1165>=Analysis!L31),ROW('Meter Type Data'!$B$2:$B$1165))-1,4))," ",INDEX('Meter Type Data'!$B$2:$E$1165,SUMPRODUCT(--('Meter Type Data'!$B$2:$B$1165<=Analysis!L31)*('Meter Type Data'!$C$2:$C$1165>=Analysis!L31),ROW('Meter Type Data'!$B$2:$B$1165))-1,4)) | N31: =IF(ISERROR(INDEX('Meter Type Data'!$B$2:$D$1165,SUMPRODUCT(--('Meter Type Data'!$B$2:$B$1165<=Analysis!L31)*('Meter Type Data'!$C$2:$C$1165>=Analysis!L31),ROW('Meter Type Data'!$B$2:$B$1165))-1,3))," ",INDEX('Meter Type Data'!$B$2:$D$1165,SUMPRODUCT(--('Meter Type Data'!$B$2:$B$1165<=Analysis!L31)*('Meter Type Data'!$C$2:$C$1165>=Analysis!L31),ROW('Meter Type Data'!$B$2:$B$1165))-1,3)) | R31: =(($O31*P31)/100)+(Q31*12) | U31: =(($O31*S31)/100)+(T31*12) | X31: =(($O31*V31)/100)+(W31*12) | AA31: =(($O31*Y31)/100)+(Z31*12) | AD31: =(($O31*AB31)/100)+(AC31*12) | AG31: =(($O31*AE31)/100)+(AF31*12) | AJ31: =(($O31*AH31)/100)+(AI31*12) | AM31: =(($O31*AK31)/100)+(AL31*12) | AP31: =(($O31*AN31)/100)+(AO31*12) | AS31: =(($O31*AQ31)/100)+(AR31*12) | AV31: =(($O31*AT31)/100)+(AU31*12) | AY31: =(($O31*AW31)/100)+(AX31*12) | BB31: =(($O31*AZ31)/100)+(BA31*12) | BE31: =(($O31*BC31)/100)+(BD31*12) | BH31: =(($O31*BF31)/100)+(BG31*12) | BK31: =(($O31*BI31)/100)+(BJ31*12) | BN31: =(($O31*BL31)/100)+(BM31*12) | BQ31: =(($O31*BO31)/100)+(BP31*12) | BT31: =(($O31*BR31)/100)+(BS31*12) | BW31: =(($O31*BU31)/100)+(BV31*12) | BZ31: =(($O31*BX31)/100)+(BY31*12) | CC31: =(($O31*CA31)/100)+(CB31*12) | CF31: =(($O31*CD31)/100)+(CE31*12) | CI31: =(($O31*CG31)/100)+(CH31*12) | CL31: =(($O31*CJ31)/100)+(CK31*12) | CO31: =(($O31*CM31)/100)+(CN31*12) | CR31: =(($O31*CP31)/100)+(CQ31*12) | CU31: =(($O31*CS31)/100)+(CT31*12)
M32: =IF(ISERROR(INDEX('Meter Type Data'!$B$2:$E$1165,SUMPRODUCT(--('Meter Type Data'!$B$2:$B$1165<=Analysis!L32)*('Meter Type Data'!$C$2:$C$1165>=Analysis!L32),ROW('Meter Type Data'!$B$2:$B$1165))-1,4))," ",INDEX('Meter Type Data'!$B$2:$E$1165,SUMPRODUCT(--('Meter Type Data'!$B$2:$B$1165<=Analysis!L32)*('Meter Type Data'!$C$2:$C$1165>=Analysis!L32),ROW('Meter Type Data'!$B$2:$B$1165))-1,4)) | N32: =IF(ISERROR(INDEX('Meter Type Data'!$B$2:$D$1165,SUMPRODUCT(--('Meter Type Data'!$B$2:$B$1165<=Analysis!L32)*('Meter Type Data'!$C$2:$C$1165>=Analysis!L32),ROW('Meter Type Data'!$B$2:$B$1165))-1,3))," ",INDEX('Meter Type Data'!$B$2:$D$1165,SUMPRODUCT(--('Meter Type Data'!$B$2:$B$1165<=Analysis!L32)*('Meter Type Data'!$C$2:$C$1165>=Analysis!L32),ROW('Meter Type Data'!$B$2:$B$1165))-1,3)) | R32: =(($O32*P32)/100)+(Q32*12) | U32: =(($O32*S32)/100)+(T32*12) | X32: =(($O32*V32)/100)+(W32*12) | AA32: =(($O32*Y32)/100)+(Z32*12) | AD32: =(($O32*AB32)/100)+(AC32*12) | AG32: =(($O32*AE32)/100)+(AF32*12) | AJ32: =(($O32*AH32)/100)+(AI32*12) | AM32: =(($O32*AK32)/100)+(AL32*12) | AP32: =(($O32*AN32)/100)+(AO32*12) | AS32: =(($O32*AQ32)/100)+(AR32*12) | AV32: =(($O32*AT32)/100)+(AU32*12) | AY32: =(($O32*AW32)/100)+(AX32*12) | BB32: =(($O32*AZ32)/100)+(BA32*12) | BE32: =(($O32*BC32)/100)+(BD32*12) | BH32: =(($O32*BF32)/100)+(BG32*12) | BK32: =(($O32*BI32)/100)+(BJ32*12) | BN32: =(($O32*BL32)/100)+(BM32*12) | BQ32: =(($O32*BO32)/100)+(BP32*12) | BT32: =(($O32*BR32)/100)+(BS32*12) | BW32: =(($O32*BU32)/100)+(BV32*12) | BZ32: =(($O32*BX32)/100)+(BY32*12) | CC32: =(($O32*CA32)/100)+(CB32*12) | CF32: =(($O32*CD32)/100)+(CE32*12) | CI32: =(($O32*CG32)/100)+(CH32*12) | CL32: =(($O32*CJ32)/100)+(CK32*12) | CO32: =(($O32*CM32)/100)+(CN32*12) | CR32: =(($O32*CP32)/100)+(CQ32*12) | CU32: =(($O32*CS32)/100)+(CT32*12)
M33: =IF(ISERROR(INDEX('Meter Type Data'!$B$2:$E$1165,SUMPRODUCT(--('Meter Type Data'!$B$2:$B$1165<=Analysis!L33)*('Meter Type Data'!$C$2:$C$1165>=Analysis!L33),ROW('Meter Type Data'!$B$2:$B$1165))-1,4))," ",INDEX('Meter Type Data'!$B$2:$E$1165,SUMPRODUCT(--('Meter Type Data'!$B$2:$B$1165<=Analysis!L33)*('Meter Type Data'!$C$2:$C$1165>=Analysis!L33),ROW('Meter Type Data'!$B$2:$B$1165))-1,4)) | N33: =IF(ISERROR(INDEX('Meter Type Data'!$B$2:$D$1165,SUMPRODUCT(--('Meter Type Data'!$B$2:$B$1165<=Analysis!L33)*('Meter Type Data'!$C$2:$C$1165>=Analysis!L33),ROW('Meter Type Data'!$B$2:$B$1165))-1,3))," ",INDEX('Meter Type Data'!$B$2:$D$1165,SUMPRODUCT(--('Meter Type Data'!$B$2:$B$1165<=Analysis!L33)*('Meter Type Data'!$C$2:$C$1165>=Analysis!L33),ROW('Meter Type Data'!$B$2:$B$1165))-1,3)) | R33: =(($O33*P33)/100)+(Q33*12) | U33: =(($O33*S33)/100)+(T33*12) | X33: =(($O33*V33)/100)+(W33*12) | AA33: =(($O33*Y33)/100)+(Z33*12) | AD33: =(($O33*AB33)/100)+(AC33*12) | AG33: =(($O33*AE33)/100)+(AF33*12) | AJ33: =(($O33*AH33)/100)+(AI33*12) | AM33: =(($O33*AK33)/100)+(AL33*12) | AP33: =(($O33*AN33)/100)+(AO33*12) | AS33: =(($O33*AQ33)/100)+(AR33*12) | AV33: =(($O33*AT33)/100)+(AU33*12) | AY33: =(($O33*AW33)/100)+(AX33*12) | BB33: =(($O33*AZ33)/100)+(BA33*12) | BE33: =(($O33*BC33)/100)+(BD33*12) | BH33: =(($O33*BF33)/100)+(BG33*12) | BK33: =(($O33*BI33)/100)+(BJ33*12) | BN33: =(($O33*BL33)/100)+(BM33*12) | BQ33: =(($O33*BO33)/100)+(BP33*12) | BT33: =(($O33*BR33)/100)+(BS33*12) | BW33: =(($O33*BU33)/100)+(BV33*12) | BZ33: =(($O33*BX33)/100)+(BY33*12) | CC33: =(($O33*CA33)/100)+(CB33*12) | CF33: =(($O33*CD33)/100)+(CE33*12) | CI33: =(($O33*CG33)/100)+(CH33*12) | CL33: =(($O33*CJ33)/100)+(CK33*12) | CO33: =(($O33*CM33)/100)+(CN33*12) | CR33: =(($O33*CP33)/100)+(CQ33*12) | CU33: =(($O33*CS33)/100)+(CT33*12)
